Workbook

Sheet LEIA-ME
A1: ALLIK ONE — PLANILHA OFICIAL DE ESTOQUE
A2: Versão 1.0 · Modelo para conferência física, saneamento cadastral e importação auditável
A4: OBJETIVO | B4: Registrar o estoque real por unidade, local, produto e lote antes da atualização do Allik One.
A5: 1. PRODUTOS | B5: Revise SKU, nome, categoria, unidade de medida e estoque mínimo. Não reutilize um SKU para produtos diferentes.
A6: 2. CONTAGEM_FISICA | B6: Use uma linha para cada combinação de unidade + local + SKU + lote. Se houver dois lotes do mesmo produto, use duas linhas.
A7: 3. CAMPOS OBRIGATÓRIOS | B7: Unidade, local, SKU, lote, validade, status, quantidade física, custo unitário, fornecedor, data e responsável.
A8: 4. LOTE DESCONHECIDO | B8: Não invente o lote. Separe o item e informe SEM LOTE na observação; a liberação excepcional será decidida antes da importação.
A9: 5. VALIDADE | B9: Use uma data real. Não estimar validade. Produto vencido deve permanecer registrado e receber status BLOQUEADO.
A10: 6. CUSTO | B10: Informe o custo de aquisição por unidade de medida do cadastro, não o preço de venda. Use vírgula ou ponto conforme o Excel.
A11: 7. QUANTIDADE | B11: Conte na mesma unidade indicada em PRODUTOS. Não misture caixa, frasco, ampola e kit na mesma linha.
A12: 8. CONFERÊNCIA | B12: Depois do primeiro preenchimento, uma segunda pessoa deve revisar e preencher Segunda conferência por.
A13: 9. IMPORTAÇÃO | B13: Somente linhas com IMPORTAR = SIM e VALIDAÇÃO = OK serão consideradas. O sistema criará movimentos auditáveis; não haverá alteração direta de saldo.
A14: 10. SEGURANÇA | B14: Não inclua dados de pacientes, senhas, tokens ou credenciais nesta planilha.

Sheet NOMENCLATURA_ATIVOS
A1: NOMENCLATURA OFICIAL DOS ATIVOS
A2: O nome padronizado descreve composição/concentração/apresentação e via. Não representa prescrição individual nem frequência de administração.
A3: SKU cadastrado | B3: Nome anterior | C3: Nome operacional padronizado | D3: Código no catálogo fornecedor | E3: Composição/concentração | F3: Via | G3: Fornecedor informado | H3: Situação | I3: Ação necessária
A4: JDO-001-IM-ADEK | B4: ADEK | C4: ADEK 600.000 UI/1 mL IM | D4: STIN-P007 | E4: Vit. D3 600.000 UI + Vit. K2-MK7 1.300 mcg + Vit. A 50.000 UI + Vit. E 500 UI | F4: IM | G4: Stin Pharma | H4: CONFIRMADO | I4: Nenhuma
A5: JDO-002-IM-ANTI-INFLAMATORIO-E-ANTIOXID | B5: ANTI INFLAMATORIO E ANTIOXIDANTE | C5: Anti-inflamatório e Antioxidante — Protocolo EV 1.5 | D5: ESS-EV1-5-P | E5: MSM 750 mg/5 mL + NAC 300 mg/2 mL + L-Carnitina 600 mg/2 mL + Complexo B sem B1 + SAME 200 mg/2 mL + Aminoácidos | F5: EV | G5: Essentia Pharma | H5: DIVERGÊNCIA DE VIA: SKU DIZ IM | I5: Conferir foto do rótulo/embalagem antes de renomear ou importar
A6: JDO-003-IM-BOOSTER-ATP | B6: BOOSTER ATP | C6: Booster Energético — ATP 20 mg + L-Carnitina 600 mg + PQQ 5 mg/2 mL EV/IM | D6: STIN-P014 | E6: ATP 20 mg + L-Carnitina 600 mg + PQQ 5 mg em 2 mL | F6: EV/IM | G6: Stin Pharma | H6: CONFIRMADO | I6: Nenhuma
A7: JDO-004-IM-BOOSTER-MOROSIL | B7: BOOSTER MOROSIL | C7: Booster Morosil — concentração a confirmar — IM | E7: Composição e apresentação não localizadas nos catálogos cadastrados | F7: IM | G7: Central Pharma | H7: CONFIRMAR RÓTULO | I7: Conferir foto do rótulo/embalagem antes de renomear ou importar
A8: JDO-005-IM-COENZIMA-Q10 | B8: COENZIMA Q10 | C8: Coenzima Q10 100 mg/2 mL IM | D8: STIN-P023 | E8: Coenzima Q10 50 mg/mL; total 100 mg em 2 mL | F8: IM | G8: Stin Pharma/Central | H8: CONFIRMADO | I8: Nenhuma
A9: JDO-006-IM-CURCUMINA | B9: CURCUMINA | C9: Curcumina 200 mg/2 mL IM | D9: STIN-P032 | E9: Curcumina 100 mg/mL; total 200 mg em 2 mL | F9: IM | G9: Stin Pharma | H9: CONFIRMADO | I9: Nenhuma
A10: JDO-007-IM-INSULIN-SUPPORT | B10: INSULIN SUPPORT | C10: Insulin Support 5 mL IM | D10: STIN-P047 | E10: Cromo Picolinato 100 mcg/mL + Inositol 100 mg/mL + Ácido Alfa-lipoico 10 mg/mL | F10: IM | G10: Stin Pharma | H10: CONFIRMAR VOLUME COM FORNECEDOR | I10: Conferir foto do rótulo/embalagem antes de renomear ou importar
A11: JDO-008-IM-L-GLUTATION | B11: L GLUTATION | C11: L-Glutationa 600 mg/5 mL EV/IM | D11: STIN-P055 | E11: L-Glutationa 600 mg em 5 mL | F11: EV/IM | G11: Stin Pharma | H11: CONFIRMADO | I11: Nenhuma
A12: JDO-009-IM-NADH | B12: NADH | C12: NADH 50 mg — pó estéril para reconstituição — IM | D12: STIN-P075 | E12: NADH 50 mg por frasco; volume de reconstituição não informado | F12: IM | G12: Stin Pharma | H12: CONFIRMAR RECONSTITUIÇÃO | I12: Conferir foto do rótulo/embalagem antes de renomear ou importar
A13: JDO-010-IM-NANDROLONA-DECANOATO | B13: NANDROLONA DECANOATO | C13: Nandrolona Decanoato — concentração a confirmar — IM | E13: Há apresentações diferentes; o produto não foi localizado no catálogo Stin cadastrado | F13: IM | G13: Stin Pharma | H13: CONFIRMAR RÓTULO | I13: Conferir foto do rótulo/embalagem antes de renomear ou importar
A14: JDO-011-EVIM-POOL-COGNITIVO-NEURO-HEALTH | B14: POOL COGNITIVO (NEURO HEALTH) | C14: Pool Cognitivo — composição a confirmar — EV/IM | E14: Fornecedor informado como Central Pharma; confirmar composição e volume no rótulo | F14: EV/IM | G14: Central Pharma | H14: CONFIRMAR RÓTULO | I14: Conferir foto do rótulo/embalagem antes de renomear ou importar
A15: JDO-012-IM-RESVERATROL | B15: RESVERATROL | C15: Resveratrol 10 mg/1 mL IM/SC | D15: STIN-P089 | E15: Resveratrol 10 mg em 1 mL | F15: IM/SC | G15: Stin Pharma | H15: CONFIRMADO | I15: Nenhuma
A16: JDO-013-IM-RESVERATROL-MICELAR | B16: RESVERATROL MICELAR | C16: Nanomicelas de Resveratrol 10 mg/1 mL EV/IM | D16: ESS-P111 | E16: Nanomicelas de Resveratrol 1%; 10 mg em 1 mL | F16: EV/IM | G16: Essentia Pharma | H16: CONFIRMADO | I16: Nenhuma
A17: JDO-014-IM-TESTOSTERONA-CIPIONATO | B17: TESTOSTERONA CIPIONATO | C17: Testosterona Cipionato — concentração a confirmar — IM | E17: Concentração e apresentação não confirmadas pelo fornecedor informado | F17: IM | G17: Stin Pharma | H17: CONFIRMAR RÓTULO | I17: Conferir foto do rótulo/embalagem antes de renomear ou importar
A18: JDO-015-IM-TESTOSTERONA-DURATESTON | B18: TESTOSTERONA DURATESTON | C18: Testosterona Durateston — composição/concentração a confirmar — IM | E18: Apresentação não localizada no catálogo Stin cadastrado | F18: IM | G18: Stin Pharma | H18: CONFIRMAR RÓTULO | I18: Conferir foto do rótulo/embalagem antes de renomear ou importar
A19: JDO-016-IM-TRIO-METILADOR | B19: TRIO METILADOR | C19: Trio Metilador 2 mL EV/IM | D19: STIN-P096 | E19: Vit. B6 30 mg + Metilfolato 3.500 mcg + Vit. B12 2.500 mcg | F19: EV/IM | G19: Stin Pharma/Central | H19: CONFIRMADO | I19: Nenhuma
A20: JDO-017-IM-TRIO-DETOX | B20: TRIO DETOX | C20: Trio Detox — composição/concentração a confirmar — IM | E20: Composição não localizada nos catálogos cadastrados | F20: IM | G20: Central Pharma | H20: CONFIRMAR RÓTULO | I20: Conferir foto do rótulo/embalagem antes de renomear ou importar
A21: JDO-018-IM-VITAMINA-B12 | B21: VITAMINA B12 | C21: Vitamina B12 — forma e concentração a confirmar — IM | E21: Catálogo possui cianocobalamina e metilcobalamina em várias concentrações | F21: IM | G21: Stin Pharma | H21: CONFIRMAR RÓTULO | I21: Conferir foto do rótulo/embalagem antes de renomear ou importar
A22: JDO-019-IM-VITAMINA-D3 | B22: VITAMINA D3 | C22: Vitamina D3 600.000 UI/1 mL IM | D22: STIN-P114 | E22: Vitamina D3 600.000 UI/mL; ampola de 1 mL | F22: IM | G22: Stin Pharma | H22: CONFIRMADO | I22: Nenhuma
A23: JDO-020-EV-ALFA-LIPOICO-300 | B23: ALFA LIPOICO 300 | C23: Ácido Alfa-lipoico 300 mg/5 mL EV | D23: STIN-P004 | E23: Ácido Alfa-lipoico 60 mg/mL; total 300 mg em 5 mL | F23: EV/IM | G23: Stin Pharma | H23: CONFIRMADO; SKU RESTRINGE EV | I23: Conferir foto do rótulo/embalagem antes de renomear ou importar
A24: JDO-021-EV-ALFA-LIPOICO-600 | B24: ALFA LIPOICO 600 | C24: Ácido Alfa-lipoico 600 mg/30 mL EV | D24: STIN-P002 | E24: Ácido Alfa-lipoico 600 mg em 30 mL | F24: EV | G24: Stin Pharma | H24: CONFIRMADO | I24: Nenhuma
A25: JDO-022-EV-ANTI-INFLAMATORIO-E-ANTIOXID | B25: ANTI INFLAMATORIO E ANTIOXIDANTE | C25: Anti-inflamatório e Antioxidante — Protocolo EV 1.5 | D25: ESS-EV1-5-P | E25: MSM 750 mg/5 mL + NAC 300 mg/2 mL + L-Carnitina 600 mg/2 mL + Complexo B sem B1 + SAME 200 mg/2 mL + Aminoácidos | F25: EV | G25: Essentia Pharma | H25: CONFIRMADO | I25: Nenhuma
A26: JDO-023-EV-COGNICAO-E-MEMORIA-PLUS | B26: COGNIÇÃO E MEMÓRIA PLUS | C26: Cognição e Memória Plus — Protocolo EV 3.10 | D26: ESS-EV3-10-P | E26: Piracetam + L-Theanina + Inositol/Taurina + L-Fenilalanina + ATP + Aminoácidos + Alfa-GPC + Colina/L-Carnitina/B5 | F26: EV | G26: Essentia Pharma | H26: CONFIRMADO | I26: Nenhuma
A27: JDO-024-EV-DISBIOSE | B27: DISBIOSE | C27: Disbiose — composição a confirmar — EV | E27: Fornecedor informado como Stin; correspondência encontrada apenas no catálogo Essentia | F27: EV | G27: Stin Pharma | H27: CONFIRMAR FORNECEDOR/RÓTULO | I27: Conferir foto do rótulo/embalagem antes de renomear ou importar
A28: JDO-025-EV-ESTEATOSE-HEPATICA | B28: ESTEATOSE HEPÁTICA | C28: Esteatose Hepática — composição a confirmar — EV | E28: Fornecedor informado como Stin; correspondência encontrada apenas no catálogo Essentia | F28: EV | G28: Stin Pharma | H28: CONFIRMAR FORNECEDOR/RÓTULO | I28: Conferir foto do rótulo/embalagem antes de renomear ou importar
A29: JDO-026-EV-FADIGA-INDISPOSICAO | B29: FADIGA/INDISPOSIÇÃO | C29: Fadiga/Indisposição — Protocolo EV 2.1 | D29: ESS-EV2-1-P | E29: NAC + Magnésio + Metilcobalamina + Complexo B sem B1 + D-Ribose + Taurina + Aminoácidos + Inositol | F29: EV | G29: Essentia Pharma | H29: CONFIRMADO | I29: Nenhuma
A30: JDO-027-EV-FADIGA-MUSCULAR-E-HIPERTROFI | B30: FADIGA MUSCULAR E HIPERTROFIA | C30: Fadiga Muscular e Hipertrofia — composição a confirmar — EV | E30: Composição exata não localizada com esse nome no catálogo Stin cadastrado | F30: EV | G30: Stin Pharma | H30: CONFIRMAR RÓTULO | I30: Conferir foto do rótulo/embalagem antes de renomear ou importar
A31: JDO-028-EV-FERRO | B31: FERRO | C31: Ferro — princípio ativo, concentração e volume a confirmar — EV | E31: Não assumir carboximaltose sem conferir rótulo e fornecedor | F31: EV | G31: Farmácia | H31: CONFIRMAR RÓTULO | I31: Conferir foto do rótulo/embalagem antes de renomear ou importar
A32: JDO-029-EV-IMUNIDADE | B32: IMUNIDADE | C32: Imunidade — Protocolo EV 1.1 | D32: ESS-EV1-1-P | E32: Alanil Glutamina + Complexo B sem B1 + NAC + L-Glutationa + Minerais | F32: EV | G32: Essentia Pharma | H32: CONFIRMADO | I32: Nenhuma
A33: JDO-030-EV-L-BAIBA | B33: L BAIBA | C33: L-BAIBA 100 mg/1 mL EV | D33: ESS-P074 | E33: Ácido L-β-aminoisobutírico 10%; 100 mg em 1 mL | F33: EV/IM | G33: Essentia Pharma | H33: CONFIRMADO; SKU RESTRINGE EV | I33: Conferir foto do rótulo/embalagem antes de renomear ou importar
A34: JDO-031-EV-L-GLUTATION | B34: L GLUTATION | C34: L-Glutationa 600 mg/5 mL EV | D34: STIN-P055 | E34: L-Glutationa 600 mg em 5 mL | F34: EV/IM | G34: Stin Pharma | H34: CONFIRMADO; SKU RESTRINGE EV | I34: Conferir foto do rótulo/embalagem antes de renomear ou importar
A35: JDO-032-Outra-LIDOCAINA | B35: LIDOCAÍNA | C35: Lidocaína — concentração, volume e via a confirmar | E35: Existem várias concentrações e apresentações; conferir rótulo | G35: Stin Pharma | H35: CONFIRMAR RÓTULO | I35: Conferir foto do rótulo/embalagem antes de renomear ou importar
A36: JDO-033-EV-RESISTENCIA-INSULINICA | B36: RESISTÊNCIA INSULÍNICA | C36: Resistência Insulínica — Protocolo EV 8.3 | D36: ESS-EV8-3-P | E36: Minerais + L-Arginina + NAC + Cromo + Complexo B sem B1 + Magnésio + Vanádio | F36: EV | G36: Essentia Pharma | H36: CONFIRMADO | I36: Nenhuma

Sheet PRODUTOS
A1: CADASTRO OFICIAL DE PRODUTOS
A2: Revise o cadastro mestre. Campos com * são obrigatórios. Preço de venda é apenas referência comercial e não substitui o custo do lote.
A3: SKU* | B3: Produto* | C3: Categoria* | D3: Unidade de medida* | E3: Estoque mínimo | F3: Preço de venda referência | G3: Rota | H3: Ativo?* | I3: Controla estoque?* | J3: Observações
A4: JDO-001-IM-ADEK | B4: ADEK 600.000 UI/1 mL IM | C4: Injetáveis | D4: Caixa | E4: 20 | F4: 600 | G4: IM | H4: SIM | I4: SIM
A5: JDO-002-IM-ANTI-INFLAMATORIO-E-ANTIOXID | B5: ANTI INFLAMATORIO E ANTIOXIDANTE | C5: Injetáveis | D5: Kit | E5: 20 | G5: IM | H5: SIM | I5: SIM | J5: DIVERGÊNCIA DE VIA: SKU DIZ IM
A6: JDO-003-IM-BOOSTER-ATP | B6: Booster Energético — ATP 20 mg + L-Carnitina 600 mg + PQQ 5 mg/2 mL EV/IM | C6: Injetáveis | D6: Caixa | E6: 30 | F6: 350 | G6: IM | H6: SIM | I6: SIM
A7: JDO-004-IM-BOOSTER-MOROSIL | B7: BOOSTER MOROSIL | C7: Injetáveis | D7: Caixa | E7: 20 | G7: IM | H7: SIM | I7: SIM | J7: CONFIRMAR RÓTULO
A8: JDO-005-IM-COENZIMA-Q10 | B8: Coenzima Q10 100 mg/2 mL IM | C8: Injetáveis | D8: Caixa | E8: 30 | F8: 350 | G8: IM | H8: SIM | I8: SIM
A9: JDO-006-IM-CURCUMINA | B9: Curcumina 200 mg/2 mL IM | C9: Injetáveis | D9: Caixa | E9: 30 | F9: 250 | G9: IM | H9: SIM | I9: SIM
A10: JDO-007-IM-INSULIN-SUPPORT | B10: INSULIN SUPPORT | C10: Injetáveis | D10: Frasco-ampola | E10: 30 | F10: 500 | G10: IM | H10: SIM | I10: SIM | J10: CONFIRMAR VOLUME COM FORNECEDOR
A11: JDO-008-IM-L-GLUTATION | B11: L-Glutationa 600 mg/5 mL EV/IM | C11: Injetáveis | D11: Caixa | E11: 0 | G11: IM | H11: SIM | I11: SIM
A12: JDO-009-IM-NADH | B12: NADH | C12: Injetáveis | D12: Frasco-ampola | E12: 20 | F12: 560 | G12: IM | H12: SIM | I12: SIM | J12: CONFIRMAR RECONSTITUIÇÃO
A13: JDO-010-IM-NANDROLONA-DECANOATO | B13: NANDROLONA DECANOATO | C13: Injetáveis | D13: Ampola | E13: 10 | F13: 620 | G13: IM | H13: SIM | I13: SIM | J13: CONFIRMAR RÓTULO
A14: JDO-011-EVIM-POOL-COGNITIVO-NEURO-HEALTH | B14: POOL COGNITIVO (NEURO HEALTH) | C14: Injetáveis | D14: Ampola | E14: 10 | G14: EV/IM | H14: SIM | I14: SIM | J14: CONFIRMAR RÓTULO
A15: JDO-012-IM-RESVERATROL | B15: Resveratrol 10 mg/1 mL IM/SC | C15: Injetáveis | D15: Caixa | E15: 30 | F15: 350 | G15: IM | H15: SIM | I15: SIM
A16: JDO-013-IM-RESVERATROL-MICELAR | B16: Nanomicelas de Resveratrol 10 mg/1 mL EV/IM | C16: Injetáveis | D16: Caixa | E16: 30 | F16: 500 | G16: IM | H16: SIM | I16: SIM
A17: JDO-014-IM-TESTOSTERONA-CIPIONATO | B17: TESTOSTERONA CIPIONATO | C17: Injetáveis | D17: Ampola | E17: 15 | F17: 500 | G17: IM | H17: SIM | I17: SIM | J17: CONFIRMAR RÓTULO
A18: JDO-015-IM-TESTOSTERONA-DURATESTON | B18: TESTOSTERONA DURATESTON | C18: Injetáveis | D18: Frasco-ampola | E18: 15 | F18: 650 | G18: IM | H18: SIM | I18: SIM | J18: CONFIRMAR RÓTULO
A19: JDO-016-IM-TRIO-METILADOR | B19: Trio Metilador 2 mL EV/IM | C19: Injetáveis | D19: Caixa | E19: 10 | F19: 490 | G19: IM | H19: SIM | I19: SIM
A20: JDO-017-IM-TRIO-DETOX | B20: TRIO DETOX | C20: Injetáveis | D20: Caixa | E20: 20 | F20: 300 | G20: IM | H20: SIM | I20: SIM | J20: CONFIRMAR RÓTULO
A21: JDO-018-IM-VITAMINA-B12 | B21: VITAMINA B12 | C21: Injetáveis | D21: Caixa | E21: 20 | F21: 250 | G21: IM | H21: SIM | I21: SIM | J21: CONFIRMAR RÓTULO
A22: JDO-019-IM-VITAMINA-D3 | B22: Vitamina D3 600.000 UI/1 mL IM | C22: Injetáveis | D22: Caixa | E22: 10 | G22: IM | H22: SIM | I22: SIM
A23: JDO-020-EV-ALFA-LIPOICO-300 | B23: ALFA LIPOICO 300 | C23: Injetáveis | D23: Caixa | E23: 10 | G23: EV | H23: SIM | I23: SIM | J23: CONFIRMADO; SKU RESTRINGE EV
A24: JDO-021-EV-ALFA-LIPOICO-600 | B24: Ácido Alfa-lipoico 600 mg/30 mL EV | C24: Injetáveis | D24: Caixa | E24: 30 | F24: 770 | G24: EV | H24: SIM | I24: SIM
A25: JDO-022-EV-ANTI-INFLAMATORIO-E-ANTIOXID | B25: Anti-inflamatório e Antioxidante — Protocolo EV 1.5 | C25: Injetáveis | D25: Caixa | E25: 20 | G25: EV | H25: SIM | I25: SIM
A26: JDO-023-EV-COGNICAO-E-MEMORIA-PLUS | B26: Cognição e Memória Plus — Protocolo EV 3.10 | C26: Injetáveis | D26: Kit | E26: 10 | F26: 750 | G26: EV | H26: SIM | I26: SIM
A27: JDO-024-EV-DISBIOSE | B27: DISBIOSE | C27: Injetáveis | D27: Kit | E27: 10 | F27: 700 | G27: EV | H27: SIM | I27: SIM | J27: CONFIRMAR FORNECEDOR/RÓTULO
A28: JDO-025-EV-ESTEATOSE-HEPATICA | B28: ESTEATOSE HEPÁTICA | C28: Injetáveis | D28: Kit | E28: 20 | F28: 750 | G28: EV | H28: SIM | I28: SIM | J28: CONFIRMAR FORNECEDOR/RÓTULO
A29: JDO-026-EV-FADIGA-INDISPOSICAO | B29: Fadiga/Indisposição — Protocolo EV 2.1 | C29: Injetáveis | D29: Kit | E29: 20 | G29: EV | H29: SIM | I29: SIM
A30: JDO-027-EV-FADIGA-MUSCULAR-E-HIPERTROFI | B30: FADIGA MUSCULAR E HIPERTROFIA | C30: Injetáveis | D30: Kit | E30: 20 | F30: 750 | G30: EV | H30: SIM | I30: SIM | J30: CONFIRMAR RÓTULO
A31: JDO-028-EV-FERRO | B31: FERRO | C31: Injetáveis | D31: Ampola | E31: 10 | F31: 270 | G31: EV | H31: SIM | I31: SIM | J31: CONFIRMAR RÓTULO
A32: JDO-029-EV-IMUNIDADE | B32: Imunidade — Protocolo EV 1.1 | C32: Injetáveis | D32: Kit | E32: 10 | F32: 700 | G32: EV | H32: SIM | I32: SIM
A33: JDO-030-EV-L-BAIBA | B33: L BAIBA | C33: Injetáveis | D33: Kit | E33: 20 | G33: EV | H33: SIM | I33: SIM | J33: CONFIRMADO; SKU RESTRINGE EV
A34: JDO-031-EV-L-GLUTATION | B34: L GLUTATION | C34: Injetáveis | D34: Caixa | E34: 20 | G34: EV | H34: SIM | I34: SIM | J34: CONFIRMADO; SKU RESTRINGE EV
A35: JDO-032-Outra-LIDOCAINA | B35: LIDOCAÍNA | C35: Injetáveis | D35: Caixa | E35: 50 | G35: Outra | H35: SIM | I35: SIM | J35: CONFIRMAR RÓTULO
A36: JDO-033-EV-RESISTENCIA-INSULINICA | B36: Resistência Insulínica — Protocolo EV 8.3 | C36: Injetáveis | D36: Kit | E36: 20 | F36: 750 | G36: EV | H36: SIM | I36: SIM
H37: SIM | I37: SIM
H38: SIM | I38: SIM
H39: SIM | I39: SIM
H40: SIM | I40: SIM
...

Sheet CONTAGEM_FISICA
A1: CONTAGEM FÍSICA OFICIAL
A2: Uma linha por lote e local. Preencha as células amarelas; colunas azuis/cinzas são auxiliares. Não apague o histórico anterior.
A3: IMPORTAR?* | B3: Unidade* | C3: Local de estoque* | D3: SKU* | E3: Produto (automático) | F3: Lote* | G3: Validade* | H3: Status do lote* | I3: Quantidade anterior | J3: Quantidade física* | K3: Diferença | L3: Unidade de medida (automático) | M3: Custo unitário* | N3: Fornecedor* | O3: Documento/NF | P3: Data da contagem* | Q3: Contado por* | R3: Segunda conferência por | S3: Motivo/observações | T3: VALÍDAÇÃO
A4: NÃO | B4: Juazeiro do Norte | C4: Estoque Central | D4: JDO-001-IM-ADEK | E4: =IFERROR(VLOOKUP(D4,PRODUTOS!$A:$J,2,FALSE),"") | G4: 46326 | H4: DISPONÍVEL | I4: 20 | K4: =IF(J4="","",J4-I4) | L4: =IFERROR(VLOOKUP(D4,PRODUTOS!$A:$J,4,FALSE),"") | N4: Stin Pharma | T4: =IF(A4<>"SIM","NÃO MARCADA",IF(COUNTA(B4:H4,J4,M4:N4,P4:Q4)<12,"PREENCHER OBRIGATÓRIOS",IF(OR(J4<0,M4<0),"VALOR INVÁLIDO","OK")))
A5: NÃO | B5: Juazeiro do Norte | C5: Estoque Central | D5: JDO-002-IM-ANTI-INFLAMATORIO-E-ANTIOXID | E5: =IFERROR(VLOOKUP(D5,PRODUTOS!$A:$J,2,FALSE),"") | G5: 46326 | H5: DISPONÍVEL | I5: 5 | K5: =IF(J5="","",J5-I5) | L5: =IFERROR(VLOOKUP(D5,PRODUTOS!$A:$J,4,FALSE),"") | N5: Essentia Pharma | T5: =IF(A5<>"SIM","NÃO MARCADA",IF(COUNTA(B5:H5,J5,M5:N5,P5:Q5)<12,"PREENCHER OBRIGATÓRIOS",IF(OR(J5<0,M5<0),"VALOR INVÁLIDO","OK")))
A6: NÃO | B6: Juazeiro do Norte | C6: Estoque Central | D6: JDO-003-IM-BOOSTER-ATP | E6: =IFERROR(VLOOKUP(D6,PRODUTOS!$A:$J,2,FALSE),"") | G6: 46507 | H6: DISPONÍVEL | I6: 20 | K6: =IF(J6="","",J6-I6) | L6: =IFERROR(VLOOKUP(D6,PRODUTOS!$A:$J,4,FALSE),"") | N6: Stin Pharma | T6: =IF(A6<>"SIM","NÃO MARCADA",IF(COUNTA(B6:H6,J6,M6:N6,P6:Q6)<12,"PREENCHER OBRIGATÓRIOS",IF(OR(J6<0,M6<0),"VALOR INVÁLIDO","OK")))
A7: NÃO | B7: Juazeiro do Norte | C7: Estoque Central | D7: JDO-004-IM-BOOSTER-MOROSIL | E7: =IFERROR(VLOOKUP(D7,PRODUTOS!$A:$J,2,FALSE),"") | G7: 46356 | H7: DISPONÍVEL | I7: 14 | K7: =IF(J7="","",J7-I7) | L7: =IFERROR(VLOOKUP(D7,PRODUTOS!$A:$J,4,FALSE),"") | N7: Central Pharma | T7: =IF(A7<>"SIM","NÃO MARCADA",IF(COUNTA(B7:H7,J7,M7:N7,P7:Q7)<12,"PREENCHER OBRIGATÓRIOS",IF(OR(J7<0,M7<0),"VALOR INVÁLIDO","OK")))
A8: NÃO | B8: Juazeiro do Norte | C8: Estoque Central | D8: JDO-005-IM-COENZIMA-Q10 | E8: =IFERROR(VLOOKUP(D8,PRODUTOS!$A:$J,2,FALSE),"") | G8: 46568 | H8: DISPONÍVEL | I8: 18 | K8: =IF(J8="","",J8-I8) | L8: =IFERROR(VLOOKUP(D8,PRODUTOS!$A:$J,4,FALSE),"") | N8: Stin Pharma/Central | T8: =IF(A8<>"SIM","NÃO MARCADA",IF(COUNTA(B8:H8,J8,M8:N8,P8:Q8)<12,"PREENCHER OBRIGATÓRIOS",IF(OR(J8<0,M8<0),"VALOR INVÁLIDO","OK")))
A9: NÃO | B9: Juazeiro do Norte | C9: Estoque Central | D9: JDO-006-IM-CURCUMINA | E9: =IFERROR(VLOOKUP(D9,PRODUTOS!$A:$J,2,FALSE),"") | G9: 46538 | H9: DISPONÍVEL | I9: 5 | K9: =IF(J9="","",J9-I9) | L9: =IFERROR(VLOOKUP(D9,PRODUTOS!$A:$J,4,FALSE),"") | N9: Stin Pharma | T9: =IF(A9<>"SIM","NÃO MARCADA",IF(COUNTA(B9:H9,J9,M9:N9,P9:Q9)<12,"PREENCHER OBRIGATÓRIOS",IF(OR(J9<0,M9<0),"VALOR INVÁLIDO","OK")))
A10: NÃO | B10: Juazeiro do Norte | C10: Estoque Central | D10: JDO-007-IM-INSULIN-SUPPORT | E10: =IFERROR(VLOOKUP(D10,PRODUTOS!$A:$J,2,FALSE),"") | G10: 46446 | H10: DISPONÍVEL | I10: 25 | K10: =IF(J10="","",J10-I10) | L10: =IFERROR(VLOOKUP(D10,PRODUTOS!$A:$J,4,FALSE),"") | N10: Stin Pharma | T10: =IF(A10<>"SIM","NÃO MARCADA",IF(COUNTA(B10:H10,J10,M10:N10,P10:Q10)<12,"PREENCHER OBRIGATÓRIOS",IF(OR(J10<0,M10<0),"VALOR INVÁLIDO","OK")))
A11: NÃO | B11: Juazeiro do Norte | C11: Estoque Central | D11: JDO-008-IM-L-GLUTATION | E11: =IFERROR(VLOOKUP(D11,PRODUTOS!$A:$J,2,FALSE),"") | H11: DISPONÍVEL | I11: 0 | K11: =IF(J11="","",J11-I11) | L11: =IFERROR(VLOOKUP(D11,PRODUTOS!$A:$J,4,FALSE),"") | N11: Stin Pharma | T11: =IF(A11<>"SIM","NÃO MARCADA",IF(COUNTA(B11:H11,J11,M11:N11,P11:Q11)<12,"PREENCHER OBRIGATÓRIOS",IF(OR(J11<0,M11<0),"VALOR INVÁLIDO","OK")))
A12: NÃO | B12: Juazeiro do Norte | C12: Estoque Central | D12: JDO-009-IM-NADH | E12: =IFERROR(VLOOKUP(D12,PRODUTOS!$A:$J,2,FALSE),"") | G12: 46538 | H12: DISPONÍVEL | I12: 12 | K12: =IF(J12="","",J12-I12) | L12: =IFERROR(VLOOKUP(D12,PRODUTOS!$A:$J,4,FALSE),"") | N12: Stin Pharma | T12: =IF(A12<>"SIM","NÃO MARCADA",IF(COUNTA(B12:H12,J12,M12:N12,P12:Q12)<12,"PREENCHER OBRIGATÓRIOS",IF(OR(J12<0,M12<0),"VALOR INVÁLIDO","OK")))
A13: NÃO | B13: Juazeiro do Norte | C13: Estoque Central | D13: JDO-010-IM-NANDROLONA-DECANOATO | E13: =IFERROR(VLOOKUP(D13,PRODUTOS!$A:$J,2,FALSE),"") | G13: 46843 | H13: DISPONÍVEL | I13: 3 | K13: =IF(J13="","",J13-I13) | L13: =IFERROR(VLOOKUP(D13,PRODUTOS!$A:$J,4,FALSE),"") | N13: Stin Pharma | T13: =IF(A13<>"SIM","NÃO MARCADA",IF(COUNTA(B13:H13,J13,M13:N13,P13:Q13)<12,"PREENCHER OBRIGATÓRIOS",IF(OR(J13<0,M13<0),"VALOR INVÁLIDO","OK")))
A14: NÃO | B14: Juazeiro do Norte | C14: Estoque Central | D14: JDO-011-EVIM-POOL-COGNITIVO-NEURO-HEALTH | E14: =IFERROR(VLOOKUP(D14,PRODUTOS!$A:$J,2,FALSE),"") | G14: 46418 | H14: DISPONÍVEL | I14: 10 | K14: =IF(J14="","",J14-I14) | L14: =IFERROR(VLOOKUP(D14,PRODUTOS!$A:$J,4,FALSE),"") | N14: Central Pharma | T14: =IF(A14<>"SIM","NÃO MARCADA",IF(COUNTA(B14:H14,J14,M14:N14,P14:Q14)<12,"PREENCHER OBRIGATÓRIOS",IF(OR(J14<0,M14<0),"VALOR INVÁLIDO","OK")))
A15: NÃO | B15: Juazeiro do Norte | C15: Estoque Central | D15: JDO-012-IM-RESVERATROL | E15: =IFERROR(VLOOKUP(D15,PRODUTOS!$A:$J,2,FALSE),"") | G15: 46538 | H15: DISPONÍVEL | I15: 24 | K15: =IF(J15="","",J15-I15) | L15: =IFERROR(VLOOKUP(D15,PRODUTOS!$A:$J,4,FALSE),"") | N15: Stin Pharma | T15: =IF(A15<>"SIM","NÃO MARCADA",IF(COUNTA(B15:H15,J15,M15:N15,P15:Q15)<12,"PREENCHER OBRIGATÓRIOS",IF(OR(J15<0,M15<0),"VALOR INVÁLIDO","OK")))
A16: NÃO | B16: Juazeiro do Norte | C16: Estoque Central | D16: JDO-013-IM-RESVERATROL-MICELAR | E16: =IFERROR(VLOOKUP(D16,PRODUTOS!$A:$J,2,FALSE),"") | G16: 46418 | H16: DISPONÍVEL | I16: 25 | K16: =IF(J16="","",J16-I16) | L16: =IFERROR(VLOOKUP(D16,PRODUTOS!$A:$J,4,FALSE),"") | N16: Essentia Pharma | T16: =IF(A16<>"SIM","NÃO MARCADA",IF(COUNTA(B16:H16,J16,M16:N16,P16:Q16)<12,"PREENCHER OBRIGATÓRIOS",IF(OR(J16<0,M16<0),"VALOR INVÁLIDO","OK")))
A17: NÃO | B17: Juazeiro do Norte | C17: Estoque Central | D17: JDO-014-IM-TESTOSTERONA-CIPIONATO | E17: =IFERROR(VLOOKUP(D17,PRODUTOS!$A:$J,2,FALSE),"") | G17: 46507 | H17: DISPONÍVEL | I17: 25 | K17: =IF(J17="","",J17-I17) | L17: =IFERROR(VLOOKUP(D17,PRODUTOS!$A:$J,4,FALSE),"") | N17: Stin Pharma | T17: =IF(A17<>"SIM","NÃO MARCADA",IF(COUNTA(B17:H17,J17,M17:N17,P17:Q17)<12,"PREENCHER OBRIGATÓRIOS",IF(OR(J17<0,M17<0),"VALOR INVÁLIDO","OK")))
A18: NÃO | B18: Juazeiro do Norte | C18: Estoque Central | D18: JDO-015-IM-TESTOSTERONA-DURATESTON | E18: =IFERROR(VLOOKUP(D18,PRODUTOS!$A:$J,2,FALSE),"") | G18: 46538 | H18: DISPONÍVEL | I18: 6 | K18: =IF(J18="","",J18-I18) | L18: =IFERROR(VLOOKUP(D18,PRODUTOS!$A:$J,4,FALSE),"") | N18: Stin Pharma | T18: =IF(A18<>"SIM","NÃO MARCADA",IF(COUNTA(B18:H18,J18,M18:N18,P18:Q18)<12,"PREENCHER OBRIGATÓRIOS",IF(OR(J18<0,M18<0),"VALOR INVÁLIDO","OK")))
A19: NÃO | B19: Juazeiro do Norte | C19: Estoque Central | D19: JDO-016-IM-TRIO-METILADOR | E19: =IFERROR(VLOOKUP(D19,PRODUTOS!$A:$J,2,FALSE),"") | G19: 46538 | H19: DISPONÍVEL | I19: 29 | K19: =IF(J19="","",J19-I19) | L19: =IFERROR(VLOOKUP(D19,PRODUTOS!$A:$J,4,FALSE),"") | N19: Stin Pharma/Central | T19: =IF(A19<>"SIM","NÃO MARCADA",IF(COUNTA(B19:H19,J19,M19:N19,P19:Q19)<12,"PREENCHER OBRIGATÓRIOS",IF(OR(J19<0,M19<0),"VALOR INVÁLIDO","OK")))
A20: NÃO | B20: Juazeiro do Norte | C20: Estoque Central | D20: JDO-017-IM-TRIO-DETOX | E20: =IFERROR(VLOOKUP(D20,PRODUTOS!$A:$J,2,FALSE),"") | G20: 46326 | H20: DISPONÍVEL | I20: 20 | K20: =IF(J20="","",J20-I20) | L20: =IFERROR(VLOOKUP(D20,PRODUTOS!$A:$J,4,FALSE),"") | N20: Central Pharma | T20: =IF(A20<>"SIM","NÃO MARCADA",IF(COUNTA(B20:H20,J20,M20:N20,P20:Q20)<12,"PREENCHER OBRIGATÓRIOS",IF(OR(J20<0,M20<0),"VALOR INVÁLIDO","OK")))
A21: NÃO | B21: Juazeiro do Norte | C21: Estoque Central | D21: JDO-018-IM-VITAMINA-B12 | E21: =IFERROR(VLOOKUP(D21,PRODUTOS!$A:$J,2,FALSE),"") | G21: 46538 | H21: DISPONÍVEL | I21: 6 | K21: =IF(J21="","",J21-I21) | L21: =IFERROR(VLOOKUP(D21,PRODUTOS!$A:$J,4,FALSE),"") | N21: Stin Pharma | T21: =IF(A21<>"SIM","NÃO MARCADA",IF(COUNTA(B21:H21,J21,M21:N21,P21:Q21)<12,"PREENCHER OBRIGATÓRIOS",IF(OR(J21<0,M21<0),"VALOR INVÁLIDO","OK")))
A22: NÃO | B22: Juazeiro do Norte | C22: Estoque Central | D22: JDO-019-IM-VITAMINA-D3 | E22: =IFERROR(VLOOKUP(D22,PRODUTOS!$A:$J,2,FALSE),"") | G22: 46507 | H22: DISPONÍVEL | I22: 5 | K22: =IF(J22="","",J22-I22) | L22: =IFERROR(VLOOKUP(D22,PRODUTOS!$A:$J,4,FALSE),"") | N22: Stin Pharma | T22: =IF(A22<>"SIM","NÃO MARCADA",IF(COUNTA(B22:H22,J22,M22:N22,P22:Q22)<12,"PREENCHER OBRIGATÓRIOS",IF(OR(J22<0,M22<0),"VALOR INVÁLIDO","OK")))
A23: NÃO | B23: Juazeiro do Norte | C23: Estoque Central | D23: JDO-020-EV-ALFA-LIPOICO-300 | E23: =IFERROR(VLOOKUP(D23,PRODUTOS!$A:$J,2,FALSE),"") | G23: 46326 | H23: DISPONÍVEL | I23: 1 | K23: =IF(J23="","",J23-I23) | L23: =IFERROR(VLOOKUP(D23,PRODUTOS!$A:$J,4,FALSE),"") | N23: Stin Pharma | T23: =IF(A23<>"SIM","NÃO MARCADA",IF(COUNTA(B23:H23,J23,M23:N23,P23:Q23)<12,"PREENCHER OBRIGATÓRIOS",IF(OR(J23<0,M23<0),"VALOR INVÁLIDO","OK")))
... A36: NÃO | B36: Juazeiro do Norte | C36: Estoque Central | D36: JDO-033-EV-RESISTENCIA-INSULINICA | E36: =IFERROR(VLOOKUP(D36,PRODUTOS!$A:$J,2,FALSE),"") | G36: 46387 | H36: DISPONÍVEL | I36: 19 | K36: =IF(J36="","",J36-I36) | L36: =IFERROR(VLOOKUP(D36,PRODUTOS!$A:$J,4,FALSE),"") | N36: Essentia Pharma | T36: =IF(A36<>"SIM","NÃO MARCADA",IF(COUNTA(B36:H36,J36,M36:N36,P36:Q36)<12,"PREENCHER OBRIGATÓRIOS",IF(OR(J36<0,M36<0),"VALOR INVÁLIDO","OK")))
A37: NÃO | E37: =IFERROR(VLOOKUP(D37,PRODUTOS!$A:$J,2,FALSE),"") | H37: DISPONÍVEL | K37: =IF(J37="","",J37-I37) | L37: =IFERROR(VLOOKUP(D37,PRODUTOS!$A:$J,4,FALSE),"") | T37: =IF(A37<>"SIM","NÃO MARCADA",IF(COUNTA(B37:H37,J37,M37:N37,P37:Q37)<12,"PREENCHER OBRIGATÓRIOS",IF(OR(J37<0,M37<0),"VALOR INVÁLIDO","OK")))
A38: NÃO | E38: =IFERROR(VLOOKUP(D38,PRODUTOS!$A:$J,2,FALSE),"") | H38: DISPONÍVEL | K38: =IF(J38="","",J38-I38) | L38: =IFERROR(VLOOKUP(D38,PRODUTOS!$A:$J,4,FALSE),"") | T38: =IF(A38<>"SIM","NÃO MARCADA",IF(COUNTA(B38:H38,J38,M38:N38,P38:Q38)<12,"PREENCHER OBRIGATÓRIOS",IF(OR(J38<0,M38<0),"VALOR INVÁLIDO","OK")))
A39: NÃO | E39: =IFERROR(VLOOKUP(D39,PRODUTOS!$A:$J,2,FALSE),"") | H39: DISPONÍVEL | K39: =IF(J39="","",J39-I39) | L39: =IFERROR(VLOOKUP(D39,PRODUTOS!$A:$J,4,FALSE),"") | T39: =IF(A39<>"SIM","NÃO MARCADA",IF(COUNTA(B39:H39,J39,M39:N39,P39:Q39)<12,"PREENCHER OBRIGATÓRIOS",IF(OR(J39<0,M39<0),"VALOR INVÁLIDO","OK")))
A40: NÃO | E40: =IFERROR(VLOOKUP(D40,PRODUTOS!$A:$J,2,FALSE),"") | H40: DISPONÍVEL | K40: =IF(J40="","",J40-I40) | L40: =IFERROR(VLOOKUP(D40,PRODUTOS!$A:$J,4,FALSE),"") | T40: =IF(A40<>"SIM","NÃO MARCADA",IF(COUNTA(B40:H40,J40,M40:N40,P40:Q40)<12,"PREENCHER OBRIGATÓRIOS",IF(OR(J40<0,M40<0),"VALOR INVÁLIDO","OK")))
A41: NÃO | E41: =IFERROR(VLOOKUP(D41,PRODUTOS!$A:$J,2,FALSE),"") | H41: DISPONÍVEL | K41: =IF(J41="","",J41-I41) | L41: =IFERROR(VLOOKUP(D41,PRODUTOS!$A:$J,4,FALSE),"") | T41: =IF(A41<>"SIM","NÃO MARCADA",IF(COUNTA(B41:H41,J41,M41:N41,P41:Q41)<12,"PREENCHER OBRIGATÓRIOS",IF(OR(J41<0,M41<0),"VALOR INVÁLIDO","OK")))
A42: NÃO | E42: =IFERROR(VLOOKUP(D42,PRODUTOS!$A:$J,2,FALSE),"") | H42: DISPONÍVEL | K42: =IF(J42="","",J42-I42) | L42: =IFERROR(VLOOKUP(D42,PRODUTOS!$A:$J,4,FALSE),"") | T42: =IF(A42<>"SIM","NÃO MARCADA",IF(COUNTA(B42:H42,J42,M42:N42,P42:Q42)<12,"PREENCHER OBRIGATÓRIOS",IF(OR(J42<0,M42<0),"VALOR INVÁLIDO","OK")))
A43: NÃO | E43: =IFERROR(VLOOKUP(D43,PRODUTOS!$A:$J,2,FALSE),"") | H43: DISPONÍVEL | K43: =IF(J43="","",J43-I43) | L43: =IFERROR(VLOOKUP(D43,PRODUTOS!$A:$J,4,FALSE),"") | T43: =IF(A43<>"SIM","NÃO MARCADA",IF(COUNTA(B43:H43,J43,M43:N43,P43:Q43)<12,"PREENCHER OBRIGATÓRIOS",IF(OR(J43<0,M43<0),"VALOR INVÁLIDO","OK")))
A44: NÃO | E44: =IFERROR(VLOOKUP(D44,PRODUTOS!$A:$J,2,FALSE),"") | H44: DISPONÍVEL | K44: =IF(J44="","",J44-I44) | L44: =IFERROR(VLOOKUP(D44,PRODUTOS!$A:$J,4,FALSE),"") | T44: =IF(A44<>"SIM","NÃO MARCADA",IF(COUNTA(B44:H44,J44,M44:N44,P44:Q44)<12,"PREENCHER OBRIGATÓRIOS",IF(OR(J44<0,M44<0),"VALOR INVÁLIDO","OK")))
A45: NÃO | E45: =IFERROR(VLOOKUP(D45,PRODUTOS!$A:$J,2,FALSE),"") | H45: DISPONÍVEL | K45: =IF(J45="","",J45-I45) | L45: =IFERROR(VLOOKUP(D45,PRODUTOS!$A:$J,4,FALSE),"") | T45: =IF(A45<>"SIM","NÃO MARCADA",IF(COUNTA(B45:H45,J45,M45:N45,P45:Q45)<12,"PREENCHER OBRIGATÓRIOS",IF(OR(J45<0,M45<0),"VALOR INVÁLIDO","OK")))
A46: NÃO | E46: =IFERROR(VLOOKUP(D46,PRODUTOS!$A:$J,2,FALSE),"") | H46: DISPONÍVEL | K46: =IF(J46="","",J46-I46) | L46: =IFERROR(VLOOKUP(D46,PRODUTOS!$A:$J,4,FALSE),"") | T46: =IF(A46<>"SIM","NÃO MARCADA",IF(COUNTA(B46:H46,J46,M46:N46,P46:Q46)<12,"PREENCHER OBRIGATÓRIOS",IF(OR(J46<0,M46<0),"VALOR INVÁLIDO","OK")))
A47: NÃO | E47: =IFERROR(VLOOKUP(D47,PRODUTOS!$A:$J,2,FALSE),"") | H47: DISPONÍVEL | K47: =IF(J47="","",J47-I47) | L47: =IFERROR(VLOOKUP(D47,PRODUTOS!$A:$J,4,FALSE),"") | T47: =IF(A47<>"SIM","NÃO MARCADA",IF(COUNTA(B47:H47,J47,M47:N47,P47:Q47)<12,"PREENCHER OBRIGATÓRIOS",IF(OR(J47<0,M47<0),"VALOR INVÁLIDO","OK")))
A48: NÃO | E48: =IFERROR(VLOOKUP(D48,PRODUTOS!$A:$J,2,FALSE),"") | H48: DISPONÍVEL | K48: =IF(J48="","",J48-I48) | L48: =IFERROR(VLOOKUP(D48,PRODUTOS!$A:$J,4,FALSE),"") | T48: =IF(A48<>"SIM","NÃO MARCADA",IF(COUNTA(B48:H48,J48,M48:N48,P48:Q48)<12,"PREENCHER OBRIGATÓRIOS",IF(OR(J48<0,M48<0),"VALOR INVÁLIDO","OK")))
... A500: NÃO | E500: =IFERROR(VLOOKUP(D500,PRODUTOS!$A:$J,2,FALSE),"") | H500: DISPONÍVEL | K500: =IF(J500="","",J500-I500) | L500: =IFERROR(VLOOKUP(D500,PRODUTOS!$A:$J,4,FALSE),"") | T500: =IF(A500<>"SIM","NÃO MARCADA",IF(COUNTA(B500:H500,J500,M500:N500,P500:Q500)<12,"PREENCHER OBRIGATÓRIOS",IF(OR(J500<0,M500<0),"VALOR INVÁLIDO","OK")))

Sheet FORNECEDORES
A1: CADASTRO DE FORNECEDORES
A2: Use o nome oficial e mantenha os dados de contato atualizados. Não inclua credenciais.
A3: Fornecedor* | B3: CNPJ | C3: Telefone | D3: E-mail | E3: Contato | F3: Ativo?* | G3: Observações
A4: Central | F4: SIM
A5: Central Pharma | F5: SIM
A6: Essentia Pharma | C6: +55 48 8802-9876 | F6: SIM
A7: Farmácia | F7: SIM
A8: Stin Pharma | C8: +55 11 2078-1800 | F8: SIM

Sheet LISTAS
A1: Unidades de medida | B1: Rotas | C1: Status do lote | D1: Sim/Não | E1: Unidades | F1: Locais
A2: Caixa | B2: IM | C2: DISPONÍVEL | D2: SIM | E2: Fortaleza | F2: Estoque Central
A3: Kit | B3: EV | C3: QUARENTENA | D3: NÃO | E3: Juazeiro do Norte | F3: Sala de Procedimentos
A4: Frasco | B4: EV/IM | C4: BLOQUEADO | F4: Almoxarifado
A5: Ampola | B5: SC
A6: Unidade | B6: Outra
A7: Seringa
A8: Apresentação
